{"content": {"suites": {"0": {"status": {"total_pass": 1, "total_skip": 0, "total_xpass": 0, "total_xfail": 0, "total_rerun": 0, "total_fail": 4, "total_error": 0}, "tests": {"0": {"status": "FAIL", "message": "           TimeoutError: [WinError 10060] A connection attempt failed because the connected party did not properly respond after a period of time, or established connection failed because connected host has failed to respond\n       urllib3.exceptions.NewConnectionError: <urllib3.connection.HTTPSConnection object at 0x0479CC70>: Failed to establish a new connection: [WinError 10060] A connection attempt failed because the connected party did not properly respond after a period of time, or established connection failed because connected host has failed to respond\n       urllib3.exceptions.MaxRetryError: HTTPSConnectionPool(host='10.64.114.153', port=443): Max retries exceeded with url: /cda-raster-service/cellRasterWidgets/data/widget (Caused by NewConnectionError('<urllib3.connection.HTTPSConnection object at 0x0479CC70>: Failed to establish a new connection: [WinError 10060] A connection attempt failed because the connected party did not properly respond after a period of time, or established connection failed because connected host has failed to respond'))\n       requests.exceptions.ConnectionError: HTTPSConnectionPool(host='10.64.114.153', port=443): Max retries exceeded with url: /cda-raster-service/cellRasterWidgets/data/widget (Caused by NewConnectionError('<urllib3.connection.HTTPSConnection object at 0x0479CC70>: Failed to establish a new connection: [WinError 10060] A connection attempt failed because the connected party did not properly respond after a period of time, or established connection failed because connected host has failed to respond'))\n", "test_name": "test_mapview_widget_kpiStatistics[requestDict0-expectedDict0]", "rerun": "0"}, "1": {"status": "FAIL", "message": "           TimeoutError: [WinError 10060] A connection attempt failed because the connected party did not properly respond after a period of time, or established connection failed because connected host has failed to respond\n       urllib3.exceptions.NewConnectionError: <urllib3.connection.HTTPSConnection object at 0x0473C610>: Failed to establish a new connection: [WinError 10060] A connection attempt failed because the connected party did not properly respond after a period of time, or established connection failed because connected host has failed to respond\n       urllib3.exceptions.MaxRetryError: HTTPSConnectionPool(host='10.64.114.153', port=443): Max retries exceeded with url: /cda-raster-service/cellRasterWidgets/data/widget (Caused by NewConnectionError('<urllib3.connection.HTTPSConnection object at 0x0473C610>: Failed to establish a new connection: [WinError 10060] A connection attempt failed because the connected party did not properly respond after a period of time, or established connection failed because connected host has failed to respond'))\n       requests.exceptions.ConnectionError: HTTPSConnectionPool(host='10.64.114.153', port=443): Max retries exceeded with url: /cda-raster-service/cellRasterWidgets/data/widget (Caused by NewConnectionError('<urllib3.connection.HTTPSConnection object at 0x0473C610>: Failed to establish a new connection: [WinError 10060] A connection attempt failed because the connected party did not properly respond after a period of time, or established connection failed because connected host has failed to respond'))\n", "test_name": "test_mapview_widget_kpiStatistics[requestDict1-expectedDict1]", "rerun": "0"}, "2": {"status": "FAIL", "message": "           ConnectionRefusedError: [WinError 10061] No connection could be made because the target machine actively refused it\n       urllib3.exceptions.NewConnectionError: <urllib3.connection.HTTPSConnection object at 0x0471C9A0>: Failed to establish a new connection: [WinError 10061] No connection could be made because the target machine actively refused it\n       urllib3.exceptions.MaxRetryError: HTTPSConnectionPool(host='10.64.114.153', port=443): Max retries exceeded with url: /cda-raster-service/cellRasterWidgets/data/widget (Caused by NewConnectionError('<urllib3.connection.HTTPSConnection object at 0x0471C9A0>: Failed to establish a new connection: [WinError 10061] No connection could be made because the target machine actively refused it'))\n       requests.exceptions.ConnectionError: HTTPSConnectionPool(host='10.64.114.153', port=443): Max retries exceeded with url: /cda-raster-service/cellRasterWidgets/data/widget (Caused by NewConnectionError('<urllib3.connection.HTTPSConnection object at 0x0471C9A0>: Failed to establish a new connection: [WinError 10061] No connection could be made because the target machine actively refused it'))\n", "test_name": "test_mapview_widget_kpiStatistics[requestDict2-expectedDict2]", "rerun": "0"}, "3": {"status": "PASS", "message": "", "test_name": "test_mapview_widget_kpiStatistics[requestDict3-expectedDict3]", "rerun": "0"}, "4": {"status": "FAIL", "message": "       AssertionError: soft assertion failures:\n       1. [P10 validation] Expected <0.039> to be equal to <0>, but was not.\n       2. [SampleCount validation] Expected <813> to be equal to <0>, but was not.\n", "test_name": "test_mapview_widget_kpiStatistics[requestDict4-expectedDict4]", "rerun": "0"}}, "suite_name": "test_mapview.py"}}}, "date": "January 20, 2022", "start_time": 1642664136.9438517, "total_suite": 1, "status": "FAIL", "status_list": {"pass": "1", "fail": "4", "skip": "0", "error": "0", "xpass": "0", "xfail": "0", "rerun": "0"}, "total_tests": "5"}